Workbook

Sheet Contacts
A1: College | B1: City | C1: State | D1: League(s) | E1: First Name | F1: Last Name | G1: Title | H1: Email | I1: Email Type | J1: Phone | K1: Discord | L1: Contacted | M1: Interested | N1: Date Contacted | O1: Follow-Up Date | P1: Notes | Q1: Source / Program Page | R1: Info Last Seen
A2: Shelton State Community College | B2: Tuscaloosa | C2: AL | E2: Khaleb | F2: Groce | G2: Esports Coach | H2: kgroce@sheltonstate.edu | I2: Coach / program | J2: 205-391-2285 | L2: =FALSE() -> FALSE | M2: =FALSE() -> FALSE | Q2: https://athletics.sheltonstate.edu/information/directory/bios/groce-khaleb
A3: University of Arkansas Rich Mountain | B3: Mena | C3: AR | E3: Jack | F3: Harrison | G3: Esports Head Coach | H3: jharrison@uarichmountain.edu | I3: Coach / program | J3: 479-394-7622 x1431 | L3: =FALSE() -> FALSE | M3: =FALSE() -> FALSE | Q3: https://bucksathletics.prestosports.com/sports/esports/coaches/jack_harrison
A4: Mohave Community College | B4: Kingman | C4: AZ | D4: NACE | H4: amasterson@mohave.edu | I4: Admissions staff (verify) | L4: =FALSE() -> FALSE | M4: =FALSE() -> FALSE | Q4: https://en.wikipedia.org/wiki/National_Association_of_Collegiate_Esports
A5: Coastline College | B5: Fountain Valley | C5: CA | E5: Katherine | F5: Amoukhteh | G5: Esports Lead | I5: None published | L5: =FALSE() -> FALSE | M5: =FALSE() -> FALSE | P5: No public inquiry email: 714-546-7600. | Q5: https://www.cccco.edu/About-Us/News-and-Media/ccc-outlook-newsletter-archive/ivc-coastline-esports
A6: Compton College | B6: Compton | C6: CA | I6: None published | L6: =FALSE() -> FALSE | M6: =FALSE() -> FALSE | P6: No public inquiry email: 310-900-1600. | Q6: https://productiverecruit.com/athletic-scholarships/esports/iowa/iowa-western-community-college
A7: Irvine Valley College | B7: Irvine | C7: CA | E7: Adam | F7: Lopez | G7: Esports Coordinator | I7: None published | L7: =FALSE() -> FALSE | M7: =FALSE() -> FALSE | P7: No public inquiry email: 949-451-5100. | Q7: https://www.cccco.edu/About-Us/News-and-Media/ccc-outlook-newsletter-archive/ivc-coastline-esports
A8: Long Beach City College | B8: Long Beach | C8: CA | E8: Gabe | F8: Giangualano | G8: Esports Coach | I8: None published | L8: =FALSE() -> FALSE | M8: =FALSE() -> FALSE | P8: No public inquiry email: 562-938-4111. | Q8: https://lbcc.edu/showcase-1/fans-can-catch-all-exciting-action-our-youtube-channel-lbccesports9379
A9: Trinidad State College | B9: Trinidad | C9: CO | D9: NJCAAE | H9: TS.Admissions@trinidadstate.edu | I9: General inquiry (college) | L9: =FALSE() -> FALSE | M9: =FALSE() -> FALSE | Q9: https://trinidadstate.edu/esports/index.html
A10: Daytona State College | B10: Daytona Beach | C10: FL | D10: NJCAAE / NECC | E10: Sebastian | F10: Morales | G10: Esports Coordinator / Coach | I10: None published | J10: 386-506-3838 | L10: =FALSE() -> FALSE | M10: =FALSE() -> FALSE | P10: 3 straight NJCAAE Rocket League titles. Program Discord: bit.ly/DSC_EsportsDiscord No public inquiry email: 386-506-3000. | Q10: https://www.dscfalcons.com/sports/esports/coaches/sebastian_morales | R10: 2026
A11: Hawkeye Community College | B11: Waterloo | C11: IA | D11: NJCAAE | E11: Ryan | F11: Goeke | G11: Head Esports Coach | H11: holly.grimm@hawkeyecollege.edu | I11: Admissions staff (verify) | J11: 319-296-2320 x1190 | L11: =FALSE() -> FALSE | M11: =FALSE() -> FALSE | P11: Athletics office: athletics@hawkeyecollege.edu | Q11: https://redtailathletics.com/sports/esports/coaches/Ryan_Goeke_Bio | R11: 2021
A12: Iowa Central Community College | B12: Fort Dodge | C12: IA | D12: NJCAAE | E12: Sam | F12: Morlan | G12: Head eSports Coach | H12: morlan@iowacentral.edu | I12: Coach / program | J12: 515-227-0091 | L12: =FALSE() -> FALSE | M12: =FALSE() -> FALSE | Q12: https://ictritons.prestosports.com/sports/esports/coaches/morlan_sam | R12: 2022
A13: Iowa Western Community College | B13: Council Bluffs | C13: IA | D13: NJCAAE | E13: Bill | F13: Riccetti | G13: Head Esports Coach | H13: wriccetti@iwcc.edu | I13: Coach / program | L13: =FALSE() -> FALSE | M13: =FALSE() -> FALSE | P13: Head coach since 2023-24. | Q13: https://goreivers.com/sports/esports/coaches/billricetti | R13: 2025
A14: Marshalltown Community College | B14: Marshalltown | C14: IA | D14: NJCAAE | E14: Nate | F14: Rodemeyer | G14: Head Esports Coach | H14: mccinfo@iavalley.edu | I14: General inquiry (college) | J14: 641-844-5789 | L14: =FALSE() -> FALSE | M14: =FALSE() -> FALSE | P14: 2026 NAECAD College Coach of the Year. Co-coaches: Andrew Goforth, Max Pietrzak. | Q14: https://mccathletics.com/sports/esports/coaches/Nate_Rodemeyer | R14: 2026
A15: Western Iowa Tech Community College | B15: Sioux City | C15: IA | D15: NJCAAE | E15: Mike | F15: Craig | G15: Head Coach, Esports | H15: mike.craig@witcc.edu | I15: Coach / program | J15: 712-587-9688 | L15: =FALSE() -> FALSE | M15: =FALSE() -> FALSE | P15: Co-head coach: Cale Conner (cale.conner@witcc.edu). | Q15: https://bytespeed.com/naecad-collegiate-esports-guide/ | R15: 2024
A16: College of Lake County | B16: Grayslake | C16: IL | D16: NJCAAE | E16: Matthew | F16: Hixon | G16: Head Coach, E-Sports | I16: None published | L16: =FALSE() -> FALSE | M16: =FALSE() -> FALSE | P16: Previously inaugural coach at Kishwaukee College. No public inquiry email: Student recruitment 847-543-2383. | Q16: https://clclancers.com/staff-directory/matthew-hixon/28 | R16: 2024
A17: Heartland Community College | B17: Normal | C17: IL | D17: NJCAAE | E17: Cole | F17: Belcher | G17: Head Esports Coach | H17: frc@heartland.edu | I17: Athletics office | J17: 309-268-8432 (athletics) | L17: =FALSE() -> FALSE | M17: =FALSE() -> FALSE | P17: Athletics: frc@heartland.edu. 2026 NJCAAE Rocket League national runner-up. | Q17: https://www.heartland.edu/news/2024/6.2024BelcherEsportsCoach062524.html | R17: 2024
A18: Kishwaukee College | B18: Malta | C18: IL | D18: NJCAAE | H18: ghorta@kish.edu | I18: Admissions staff (verify) | L18: =FALSE() -> FALSE | M18: =FALSE() -> FALSE | Q18: https://productiverecruit.com/athletic-scholarships/esports/kansas/highland-community-college
A19: Lincoln Land Community College | B19: Springfield | C19: IL | D19: NJCAAE | H19: robin.ackman@llcc.edu | I19: Admissions staff (verify) | L19: =FALSE() -> FALSE | M19: =FALSE() -> FALSE | Q19: https://productiverecruit.com/athletic-scholarships/esports/michigan/muskegon-community-college
A20: William Rainey Harper College | B20: Palatine | C20: IL | D20: NJCAAE | I20: None published | L20: =FALSE() -> FALSE | M20: =FALSE() -> FALSE | P20: No public inquiry email: 847-925-6000; general inquiry form on harpercollege.edu. | Q20: https://productiverecruit.com/athletic-scholarships/esports/pennsylvania/montgomery-county-community-college
A21: Barton County Community College | B21: Great Bend | C21: KS | H21: admissions@bartonccc.edu | I21: General inquiry (college) | L21: =FALSE() -> FALSE | M21: =FALSE() -> FALSE | Q21: https://productiverecruit.com/athletic-scholarships/esports/kansas/highland-community-college
A22: Coffeyville Community College | B22: Coffeyville | C22: KS | D22: NACE | G22: E-Sports Coach | H22: admissions@coffeyville.edu | I22: General inquiry (college) | J22: 620-251-7700 (main) | L22: =FALSE() -> FALSE | M22: =FALSE() -> FALSE | P22: Coach page exists but name not captured; check link. Titles: LoL, OW, RL, Fortnite, R6. | Q22: https://www.coffeyville.edu/student-organizations-and-activities/esports/esports-coach
A23: Fort Scott Community College | B23: Fort Scott | C23: KS | D23: NJCAAE | E23: Ben | F23: Souza | G23: Head Esports Coach | H23: bens@fortscott.edu | I23: Coach / program | J23: 620-223-2700 x4110 | L23: =FALSE() -> FALSE | M23: =FALSE() -> FALSE | Q23: https://fortscott.prestosports.com/sports/esports/coaches/Ben_Souza | R23: 2024
A24: Hesston College | B24: Hesston | C24: KS | D24: NJCAAE | E24: Mitchell | F24: Margaris | G24: Esports Head Coach | H24: mitchell.margaris@hesston.edu | I24: Coach / program | L24: =FALSE() -> FALSE | M24: =FALSE() -> FALSE | Q24: https://hesston.edu/about/leadership-faculty-and-staff/faculty-and-staff-directory/mitchell-margaris | R24: 2025
A25: Highland Community College | B25: Highland | C25: KS | D25: NJCAAE / NACE | H25: admissions@highland.edu | I25: General inquiry (college) | L25: =FALSE() -> FALSE | M25: =FALSE() -> FALSE | P25: Coach not listed publicly. 2026 NJCAAE D1 Street Fighter 6 finalist. | Q25: https://productiverecruit.com/athletic-scholarships/esports/kansas/highland-community-college
A26: Independence Community College | B26: Independence | C26: KS | D26: NACE | H26: bthornton@indycc.edu | I26: Admissions staff (verify) | L26: =FALSE() -> FALSE | M26: =FALSE() -> FALSE | Q26: https://en.wikipedia.org/wiki/National_Association_of_Collegiate_Esports
A27: Pratt Community College | B27: Pratt | C27: KS | D27: NJCAAE / NACE | E27: Charles | F27: Keefer | G27: Head Esports Coach | H27: charlesk@prattcc.edu | I27: Coach / program | J27: 316-680-9464 | L27: =FALSE() -> FALSE | M27: =FALSE() -> FALSE | Q27: https://bytespeed.com/naecad-collegiate-esports-guide/ | R27: 2024
A28: Seward County Community College | B28: Liberal | C28: KS | D28: NJCAAE | E28: Eric | F28: Volden | G28: Head Esports Coach | H28: eric.volden@sccc.edu | I28: Coach / program | L28: =FALSE() -> FALSE | M28: =FALSE() -> FALSE | P28: Program began 2023-24. | Q28: https://seward.prestosports.com/sports/esports/coaches/Eric_Volden | R28: 2024
A29: Massachusetts Bay Community College | B29: Wellesley Hills | C29: MA | H29: admissions@massbay.edu | I29: General inquiry (college) | L29: =FALSE() -> FALSE | M29: =FALSE() -> FALSE | Q29: https://productiverecruit.com/athletic-scholarships/esports/iowa/iowa-western-community-college
A30: Northern Essex Community College | B30: Haverhill | C30: MA | H30: enrollmentservices@necc.mass.edu | I30: General inquiry (college) | L30: =FALSE() -> FALSE | M30: =FALSE() -> FALSE | Q30: https://en.wikipedia.org/wiki/College_esports_in_the_United_States
A31: Anne Arundel Community College | B31: Arnold | C31: MD | E31: Conway | F31: Johnson | G31: Head Esports Coach | H31: wcjohnson2@aacc.edu | I31: Coach / program | J31: 443-996-8509 | L31: =FALSE() -> FALSE | M31: =FALSE() -> FALSE | Q31: https://aacc.prestosports.com/sports/esports/coaches/Conway_Johnson
A32: Central Maine Community College | B32: Auburn | C32: ME | I32: None published | L32: =FALSE() -> FALSE | M32: =FALSE() -> FALSE | P32: No public inquiry email: Admissions 207-755-5273; contact form. | Q32: https://www.animationcareerreview.com/articles/list-us-colleges-varsity-esports-programs
A33: York County Community College | B33: Wells | C33: ME | D33: NJCAAE (from 2026-27) | E33: Aiden | F33: Deshaies | G33: Esports Head Coach | H33: adeshaies@mainecc.edu | I33: Coach / program | J33: 207-216-4309 | L33: =FALSE() -> FALSE | M33: =FALSE() -> FALSE | P33: Moving to NJCAAE for 2026-27. | Q33: https://yorkcountyhawks.com/ESports_makes_move_to_NJCAAe | R33: 2026
A34: Gogebic Community College | B34: Ironwood | C34: MI | D34: NJCAAE | H34: info@gogebic.edu | I34: General inquiry (college) | L34: =FALSE() -> FALSE | M34: =FALSE() -> FALSE | Q34: https://www.hawkeyecollege.edu/articles/news/hawkeye-community-college-esports-program-caps-undefeated-season-with-national-title
A35: Jackson College | B35: Jackson | C35: MI | H35: admissions@jccmi.edu | I35: General inquiry (college) | L35: =FALSE() -> FALSE | M35: =FALSE() -> FALSE | Q35: https://productiverecruit.com/athletic-scholarships/esports/kansas/highland-community-college
A36: Muskegon Community College | B36: Muskegon | C36: MI | D36: NJCAAE | E36: David | F36: Klinger | G36: Head Coach | H36: johnathon.skidmore@muskegoncc.edu | I36: Admissions staff (verify) | L36: =FALSE() -> FALSE | M36: =FALSE() -> FALSE | P36: Named at 2022 launch; college has since posted a head coach opening - confirm. | Q36: https://fox17online.com/news/local-news/muskegon-community-college-launching-esports-program | R36: 2022
A37: Northwestern Michigan College | B37: Traverse City | C37: MI | D37: NJCAAE | H37: admissions@nmc.edu | I37: General inquiry (college) | L37: =FALSE() -> FALSE | M37: =FALSE() -> FALSE | Q37: https://waketech.prestosports.com/sports/esports/2022-23/releases/20221123j6z3l4
A38: St. Clair County Community College | B38: Port Huron | C38: MI | D38: NJCAAE | H38: enrollment@sc4.edu | I38: General inquiry (college) | L38: =FALSE() -> FALSE | M38: =FALSE() -> FALSE | Q38: https://productiverecruit.com/athletic-scholarships/esports/iowa/iowa-western-community-college
A39: Crowder College | B39: Neosho | C39: MO | H39: jamesdickey@crowder.edu | I39: Admissions staff (verify) | L39: =FALSE() -> FALSE | M39: =FALSE() -> FALSE | Q39: https://en.wikipedia.org/wiki/College_esports_in_the_United_States
A40: Missouri State University-West Plains | B40: West Plains | C40: MO | D40: NJCAAE | E40: Alex | F40: Pinnon | G40: Coach | H40: apinnon@missouristate.edu | I40: Coach / program | J40: 417-255-7965 | L40: =FALSE() -> FALSE | M40: =FALSE() -> FALSE | Q40: https://bytespeed.com/naecad-collegiate-esports-guide/ | R40: 2024
...

Sheet Summary
A1: NCEO Outreach Summary
A3: Colleges on list | B3: =COUNTA(Contacts!A2:A1000) -> 112
A4: With a named contact | B4: =COUNTIF(Contacts!E2:E1000,"?*") -> 53
A5: With any email address | B5: =COUNTIF(Contacts!H2:H1000,"?*") -> 83
A6: Coach / program email | B6: =COUNTIF(Contacts!I2:I1000,"Coach / program") -> 35
A7: General / admissions / athletics | B7: =B5-B6 -> 48
A8: Contacted | B8: =COUNTIF(Contacts!L2:L1000,TRUE()) -> 0
A9: Interested | B9: =COUNTIF(Contacts!M2:M1000,TRUE()) -> 0
A10: Interest rate (of contacted) | B10: =IF(B8=0,0,B9/B8) -> 0
A11: Still to contact | B11: =B3-B8 -> 112
A14: By state
A15: State | B15: Colleges | C15: Contacted | D15: Interested
A16: AL | B16: =COUNTIF(Contacts!$C$2:$C$1000,A16) -> 1 | C16: =COUNTIFS(Contacts!$C$2:$C$1000,A16,Contacts!$L$2:$L$1000,TRUE()) -> 0 | D16: =COUNTIFS(Contacts!$C$2:$C$1000,A16,Contacts!$M$2:$M$1000,TRUE()) -> 0
A17: AR | B17: =COUNTIF(Contacts!$C$2:$C$1000,A17) -> 1 | C17: =COUNTIFS(Contacts!$C$2:$C$1000,A17,Contacts!$L$2:$L$1000,TRUE()) -> 0 | D17: =COUNTIFS(Contacts!$C$2:$C$1000,A17,Contacts!$M$2:$M$1000,TRUE()) -> 0
A18: AZ | B18: =COUNTIF(Contacts!$C$2:$C$1000,A18) -> 1 | C18: =COUNTIFS(Contacts!$C$2:$C$1000,A18,Contacts!$L$2:$L$1000,TRUE()) -> 0 | D18: =COUNTIFS(Contacts!$C$2:$C$1000,A18,Contacts!$M$2:$M$1000,TRUE()) -> 0
A19: CA | B19: =COUNTIF(Contacts!$C$2:$C$1000,A19) -> 4 | C19: =COUNTIFS(Contacts!$C$2:$C$1000,A19,Contacts!$L$2:$L$1000,TRUE()) -> 0 | D19: =COUNTIFS(Contacts!$C$2:$C$1000,A19,Contacts!$M$2:$M$1000,TRUE()) -> 0
A20: CO | B20: =COUNTIF(Contacts!$C$2:$C$1000,A20) -> 1 | C20: =COUNTIFS(Contacts!$C$2:$C$1000,A20,Contacts!$L$2:$L$1000,TRUE()) -> 0 | D20: =COUNTIFS(Contacts!$C$2:$C$1000,A20,Contacts!$M$2:$M$1000,TRUE()) -> 0
A21: FL | B21: =COUNTIF(Contacts!$C$2:$C$1000,A21) -> 1 | C21: =COUNTIFS(Contacts!$C$2:$C$1000,A21,Contacts!$L$2:$L$1000,TRUE()) -> 0 | D21: =COUNTIFS(Contacts!$C$2:$C$1000,A21,Contacts!$M$2:$M$1000,TRUE()) -> 0
A22: IA | B22: =COUNTIF(Contacts!$C$2:$C$1000,A22) -> 5 | C22: =COUNTIFS(Contacts!$C$2:$C$1000,A22,Contacts!$L$2:$L$1000,TRUE()) -> 0 | D22: =COUNTIFS(Contacts!$C$2:$C$1000,A22,Contacts!$M$2:$M$1000,TRUE()) -> 0
A23: IL | B23: =COUNTIF(Contacts!$C$2:$C$1000,A23) -> 5 | C23: =COUNTIFS(Contacts!$C$2:$C$1000,A23,Contacts!$L$2:$L$1000,TRUE()) -> 0 | D23: =COUNTIFS(Contacts!$C$2:$C$1000,A23,Contacts!$M$2:$M$1000,TRUE()) -> 0
A24: KS | B24: =COUNTIF(Contacts!$C$2:$C$1000,A24) -> 8 | C24: =COUNTIFS(Contacts!$C$2:$C$1000,A24,Contacts!$L$2:$L$1000,TRUE()) -> 0 | D24: =COUNTIFS(Contacts!$C$2:$C$1000,A24,Contacts!$M$2:$M$1000,TRUE()) -> 0
A25: MA | B25: =COUNTIF(Contacts!$C$2:$C$1000,A25) -> 2 | C25: =COUNTIFS(Contacts!$C$2:$C$1000,A25,Contacts!$L$2:$L$1000,TRUE()) -> 0 | D25: =COUNTIFS(Contacts!$C$2:$C$1000,A25,Contacts!$M$2:$M$1000,TRUE()) -> 0
A26: MD | B26: =COUNTIF(Contacts!$C$2:$C$1000,A26) -> 1 | C26: =COUNTIFS(Contacts!$C$2:$C$1000,A26,Contacts!$L$2:$L$1000,TRUE()) -> 0 | D26: =COUNTIFS(Contacts!$C$2:$C$1000,A26,Contacts!$M$2:$M$1000,TRUE()) -> 0
A27: ME | B27: =COUNTIF(Contacts!$C$2:$C$1000,A27) -> 2 | C27: =COUNTIFS(Contacts!$C$2:$C$1000,A27,Contacts!$L$2:$L$1000,TRUE()) -> 0 | D27: =COUNTIFS(Contacts!$C$2:$C$1000,A27,Contacts!$M$2:$M$1000,TRUE()) -> 0
... A48: WY | B48: =COUNTIF(Contacts!$C$2:$C$1000,A48) -> 2 | C48: =COUNTIFS(Contacts!$C$2:$C$1000,A48,Contacts!$L$2:$L$1000,TRUE()) -> 0 | D48: =COUNTIFS(Contacts!$C$2:$C$1000,A48,Contacts!$M$2:$M$1000,TRUE()) -> 0

Sheet Read Me
A1: How to use this list
A3: Contacted / Interested: set each cell to TRUE or FALSE from the dropdown. Rows turn blue when contacted and green when interested.
A4: Want real clickable checkboxes? In Excel 365: select L2:M(last row) > Insert > Checkbox. In Google Sheets: select the range > Insert > Checkbox. The TRUE/FALSE values convert automatically.
A5: Date Contacted / Follow-Up Date: enter dates (mm/dd/yyyy). Notes: free text for your call/email history.
A6: Email Type tells you who an address reaches:
A7: Coach / program = the esports coach, director, or program inbox.
A8: General inquiry (college) = the college's own info/admissions inbox, taken from its website. Ask them to forward to the esports coach.
A9: Admissions staff (verify) = a named admissions staffer from the Peterson's college directory; may be outdated, so check before sending.
A10: Athletics office = the athletics department inbox.
A11: None published = the college only offers a web form or phone; the number is in Notes.
A12: Yellow Email cells = no email found. Info Last Seen = the year of the source for coach details; confirm anything 2022 or older.
A14: How the list was built (Oct 2026)
... A17: This is not every 2-year program in the country. Good next sources: NJCAAE's competition platform standings (LeagueOS), NJCAA region pages, and asking contacts who else is in their conference.
